Workbook

Sheet 총 자산 현황
A1: 날짜 | B1: 현금 (예적금) | C1: 주식 | D1: 개인연금 | E1: 부동산 | F1: 부채 | G1: 순자산 | H1: 전월 대비 증감
A2: 2026년 3월 | B2: =sumifs('상세 자산'!E:E,'상세 자산'!A:A,'상세 자산'!A2,'상세 자산'!B:B,'상세 자산'!$B$2)+sumifs('상세 자산'!E:E,'상세 자산'!A:A,'상세 자산'!A2,'상세 자산'!B:B,'상세 자산'!$B$4) -> 201433670 | C2: =sumifs('상세 자산'!E:E,'상세 자산'!A:A,'상세 자산'!A2,'상세 자산'!B:B,'상세 자산'!$B$17)+sumifs('상세 자산'!E:E,'상세 자산'!A:A,'상세 자산'!A2,'상세 자산'!B:B,'상세 자산'!$B$28) -> 125380559 | D2: =sumifs('상세 자산'!E:E,'상세 자산'!A:A,'상세 자산'!A2,'상세 자산'!B:B,'상세 자산'!$B$9) -> 151563660 | E2: =3300000000-1100000000 -> 2200000000 | F2: ='대출'!$C$8 -> 349025014 | G2: =B2+C2+D2+E2-F2 -> 2329352875
A3: 2026년 4월 | B3: =sumifs('상세 자산'!E:E,'상세 자산'!A:A,'상세 자산'!A30,'상세 자산'!B:B,'상세 자산'!$B$2)+sumifs('상세 자산'!E:E,'상세 자산'!A:A,'상세 자산'!A30,'상세 자산'!B:B,'상세 자산'!$B$4) -> 203233670 | C3: =sumifs('상세 자산'!E:E,'상세 자산'!A:A,'상세 자산'!A30,'상세 자산'!B:B,'상세 자산'!$B$17)+sumifs('상세 자산'!E:E,'상세 자산'!A:A,'상세 자산'!A30,'상세 자산'!B:B,'상세 자산'!$B$28) -> 132465157 | D3: =sumifs('상세 자산'!E:E,'상세 자산'!A:A,'상세 자산'!A30,'상세 자산'!B:B,'상세 자산'!$B$9) -> 156698365 | E3: =3300000000-1100000000 -> 2200000000 | F3: ='대출'!$C$8 -> 349025014 | G3: =B3+C3+D3+E3-F3 -> 2343372178 | H3: =G3-G2 -> 14019303
A4: 2026년 5월 | B4: =sumifs('상세 자산'!E:E,'상세 자산'!A:A,'상세 자산'!A58,'상세 자산'!B:B,'상세 자산'!$B$2)+sumifs('상세 자산'!E:E,'상세 자산'!A:A,'상세 자산'!A58,'상세 자산'!B:B,'상세 자산'!$B$5) -> 177633670 | C4: =sumifs('상세 자산'!E:E,'상세 자산'!A:A,'상세 자산'!A58,'상세 자산'!B:B,'상세 자산'!$B$17)+sumifs('상세 자산'!E:E,'상세 자산'!A:A,'상세 자산'!A58,'상세 자산'!B:B,'상세 자산'!$B$28) -> 200073999 | D4: =sumifs('상세 자산'!E:E,'상세 자산'!A:A,'상세 자산'!A58,'상세 자산'!B:B,'상세 자산'!$B$9) -> 181925150 | E4: =3300000000-1100000000 -> 2200000000 | F4: ='대출'!$C$8 -> 349025014 | G4: =B4+C4+D4+E4-F4 -> 2410607805 | H4: =G4-G3 -> 67235627
A5: 2026년 6월 | B5: =sumifs('상세 자산'!E:E,'상세 자산'!A:A,'상세 자산'!A88,'상세 자산'!B:B,'상세 자산'!$B$2)+sumifs('상세 자산'!E:E,'상세 자산'!A:A,'상세 자산'!A88,'상세 자산'!B:B,'상세 자산'!$B$5) -> 177633670 | C5: =sumifs('상세 자산'!E:E,'상세 자산'!A:A,'상세 자산'!A88,'상세 자산'!B:B,'상세 자산'!$B$17)+sumifs('상세 자산'!E:E,'상세 자산'!A:A,'상세 자산'!A88,'상세 자산'!B:B,'상세 자산'!$B$28) -> 200073999 | D5: =sumifs('상세 자산'!E:E,'상세 자산'!A:A,'상세 자산'!A88,'상세 자산'!B:B,'상세 자산'!$B$9) -> 181925150 | E5: =3300000000-1100000000 -> 2200000000 | F5: ='대출'!$C$8 -> 349025014 | G5: =B5+C5+D5+E5-F5 -> 2410607805 | H5: =G5-G4 -> 0

Sheet 상세 자산
A1: 날짜 | B1: 자산종류 | C1: 예금주 | D1: 계좌/상품 | E1: 금액 | F1: 수익률 | G1: 목적 | H1: 만기
A2: 2026년 3월 | B2: 예금 | C2: 유나 | D2: 새마을금고 | E2: 18000000 | G2: 주택 | H2: 2026.10.13
A3: 2026년 3월 | B3: 예금 | C3: 유나 | D3: 새마을금고 | E3: 84949683 | G3: 주택 | H3: 2026.12.29
A4: 2026년 3월 | B4: 적금 | C4: 유나 | D4: 새마을금고 | E4: 11000000 | G4: 주택 | H4: 2026.04.28
A5: 2026년 3월 | B5: 적금 | C5: 유나 | D5: 새마을금고 | E5: 2700000 | G5: 저축공제 | H5: -
A6: 2026년 3월 | B6: 적금 | C6: 유나 | D6: 신한은행 | E6: 16740000 | G6: 주택청약 | H6: -
A7: 2026년 3월 | B7: 적금 | C7: 유나 | D7: 우리은행 | E7: 1500000 | G7: 차 | H7: 2026.06.19
A8: 2026년 3월 | B8: 예금 | C8: 유나 | D8: 우리은행 | E8: 10263987 | G8: 차 | H8: 2026.12.19
A9: 2026년 3월 | B9: 개인연금 | C9: 유나 | D9: TIGER 미국 S&P500 | E9: 30026150 | F9: 0.3871 | G9: 노후 | H9: -
A10: 2026년 3월 | B10: 개인연금 | C10: 유나 | D10: TIME K바이오액티브 | E10: 1329575 | F10: 0.238 | G10: 노후 | H10: -
A11: 2026년 3월 | B11: 개인연금 | C11: 유나 | D11: TIGER 글로벌AI액티브 | E11: 22763170 | F11: 0.4781 | G11: 노후 | H11: -
A12: 2026년 3월 | B12: 주식 | C12: 유나 | D12: SPY | E12: 23933235 | F12: 0.3411 | G12: 노후 | H12: -
A13: 2026년 3월 | B13: 주식 | C13: 유나 | D13: SCHD | E13: 8309375 | F13: 0.1417 | G13: 노후 | H13: -
A14: 2026년 3월 | B14: 예금 | C14: 종현 | D14: 카카오뱅크 | E14: 14400000 | G14: 차 | H14: 2026.04.16
A15: 2026년 3월 | B15: 예금 | C15: 종현 | D15: 새마을금고 | E15: 27600000 | G15: 주택 | H15: 2030.10.21
A16: 2026년 3월 | B16: 적금 | C16: 종현 | D16: 기업은행 | E16: 14280000 | G16: 주택청약 | H16: -
A17: 2026년 3월 | B17: 주식 | C17: 종현 | D17: TIME 차이나AI테크액티브 | E17: 7927425 | F17: 0.2486 | G17: 여행 | H17: -
A18: 2026년 3월 | B18: 주식 | C18: 종현 | D18: ACE 미국 S&P500 | E18: 2622900 | F18: 0.1358 | G18: 여행 | H18: -
A19: 2026년 3월 | B19: 주식 | C19: 종현 | D19: ACE 미국나스닥100 | E19: 2929500 | F19: 0.167 | G19: 여행 | H19: -
A20: 2026년 3월 | B20: 주식 | C20: 종현 | D20: 삼성전자 | E20: 37829900 | F20: 0.3144 | G20: 우리사주 | H20: -
A21: 2026년 3월 | B21: 개인연금 | C21: 종현 | D21: TIME 차이나AI테크액티브 | E21: 4615200 | F21: 0.1536 | G21: 노후 | H21: -
A22: 2026년 3월 | B22: 개인연금 | C22: 종현 | D22: ACE 미국 S&P500 | E22: 43863505 | F22: 0.1432 | G22: 노후 | H22: -
A23: 2026년 3월 | B23: 개인연금 | C23: 종현 | D23: ACE 미국나스닥100 | E23: 48966060 | F23: 0.1737 | G23: 노후 | H23: -
A24: 2026년 3월 | B24: 주식 | C24: 유주 | D24: 삼성전자 | E24: 5300000 | F24: 1.991 | G24: 자녀 | H24: -
A25: 2026년 3월 | B25: 주식 | C25: 유주 | D25: 알파벳 | E25: 5417824 | F25: 0.006 | G25: 자녀 | H25: -
A26: 2026년 3월 | B26: 주식 | C26: 유주 | D26: QQQ | E26: 13397337 | F26: -0.0253 | G26: 자녀 | H26: -
A27: 2026년 3월 | B27: 주식 | C27: 유주 | D27: S&P 500 | E27: 13734257 | F27: 0.1298 | G27: 자녀 | H27: -
A28: 2026년 3월 | B28: 가상화폐 | C28: 유주 | D28: 비트코인 | E28: 2419421 | F28: -0.2766 | G28: 자녀 | H28: -
A29: 2026년 3월 | B29: 가상화폐 | C29: 유주 | D29: 이더리움 | E29: 1559385 | F29: -0.359 | G29: 자녀 | H29: -
A30: 2026년 4월 | B30: 예금 | C30: 유나 | D30: 새마을금고 | E30: 18000000 | G30: 주택 | H30: 2026.10.13
A31: 2026년 4월 | B31: 예금 | C31: 유나 | D31: 새마을금고 | E31: 84949683 | G31: 주택 | H31: 2026.12.29
A32: 2026년 4월 | B32: 적금 | C32: 유나 | D32: 새마을금고 | E32: 12000000 | G32: 주택 | H32: 2026.04.28
A33: 2026년 4월 | B33: 적금 | C33: 유나 | D33: 새마을금고 | E33: 2800000 | G33: 저축공제 | H33: -
A34: 2026년 4월 | B34: 적금 | C34: 유나 | D34: 신한은행 | E34: 16840000 | G34: 주택청약 | H34: -
A35: 2026년 4월 | B35: 적금 | C35: 유나 | D35: 우리은행 | E35: 2000000 | G35: 차 | H35: 2026.06.19
A36: 2026년 4월 | B36: 예금 | C36: 유나 | D36: 우리은행 | E36: 10263987 | G36: 차 | H36: 2026.12.19
A37: 2026년 4월 | B37: 개인연금 | C37: 유나 | D37: TIGER 미국 S&P500 | E37: 30377050 | F37: 0.4039 | G37: 노후 | H37: -
A38: 2026년 4월 | B38: 개인연금 | C38: 유나 | D38: TIME K바이오액티브 | E38: 1164150 | F38: 0.0872 | G38: 노후 | H38: -
A39: 2026년 4월 | B39: 개인연금 | C39: 유나 | D39: TIGER 글로벌AI액티브 | E39: 25240110 | F39: 0.6389 | G39: 노후 | H39: -
A40: 2026년 4월 | B40: 주식 | C40: 유나 | D40: SPY | E40: 26156196 | F40: 0.3165 | G40: 노후 | H40: -
...

Sheet 대출
A1: 예금주 | B1: 은행 | C1: 금액 | D1: 금리 | E1: 월납입금
A2: 종현 | B2: 새마을금고 | C2: 21640000 | D2: 0.0329 | E2: =C2*D2/12 -> 59329.667
A3: 종현 | B3: 새마을금고 | C3: 100000000 | D3: 0.0349 | E3: =C3*D3/12 -> 290833.33
A4: 종현 | B4: 새마을금고 | C4: 50000000 | D4: 0.0339 | E4: =C4*D4/12 -> 141250
A5: 종현 | B5: 우리은행 | C5: 65385014 | D5: 0.037 | E5: =C5*D5/12 -> 201603.79
A6: 유나 | B6: 새마을금고 | C6: 112000000 | D6: 0.0339 | E6: =C6*D6/12 -> 316400
A7: 유나 | B7: 하나은행 | C7: 50000000 | D7: 0.05435 | E7: -
A8: 총액 | C8: =sum(C2:C6) -> 349025014 | E8: =sum(E2:E6) -> 1009416.8

Sheet 목적별 현황
